Traceback (most recent call last):
  File "/opt/hostedtoolcache/Python/3.9.18/x64/lib/python3.9/site-packages/jupyter_cache/executors/utils.py", line 58, in single_nb_execution
    executenb(
  File "/opt/hostedtoolcache/Python/3.9.18/x64/lib/python3.9/site-packages/nbclient/client.py", line 1305, in execute
    return NotebookClient(nb=nb, resources=resources, km=km, **kwargs).execute()
  File "/opt/hostedtoolcache/Python/3.9.18/x64/lib/python3.9/site-packages/jupyter_core/utils/__init__.py", line 173, in wrapped
    return loop.run_until_complete(inner)
  File "/opt/hostedtoolcache/Python/3.9.18/x64/lib/python3.9/asyncio/base_events.py", line 647, in run_until_complete
    return future.result()
  File "/opt/hostedtoolcache/Python/3.9.18/x64/lib/python3.9/site-packages/nbclient/client.py", line 705, in async_execute
    await self.async_execute_cell(
  File "/opt/hostedtoolcache/Python/3.9.18/x64/lib/python3.9/site-packages/nbclient/client.py", line 1058, in async_execute_cell
    await self._check_raise_for_error(cell, cell_index, exec_reply)
  File "/opt/hostedtoolcache/Python/3.9.18/x64/lib/python3.9/site-packages/nbclient/client.py", line 914, in _check_raise_for_error
    raise CellExecutionError.from_cell_and_msg(cell, exec_reply_content)
nbclient.exceptions.CellExecutionError: An error occurred while executing the following cell:
------------------
A = TensorMap(randn, ComplexF64, S1, S2)
partition = ((1, 2), (3, 4, 5))
Q, P = leftorth(A, partition....; alg=Polar())
@test permute(A, partition) ≈ Q * P
@test Q' * Q ≈ id(domain(Q))
------------------


syntax: missing comma or ) in argument list

Stacktrace:
 [1] top-level scope
   @ In[9]:3

